Workbook

Sheet Gantt
A1: Induplac IoT – Carta Gantt
B2: Fecha de inicio (lunes de la semana 1): | C2: 46300
B3: S1–S3: desarrollo del MVP con Scrum (ya en ejecución) · S4–S12: implementación en Induplac con fases PMI hasta la puesta en marcha.
K5: =$C$2+7*(K$6-1) | L5: =$C$2+7*(L$6-1) | M5: =$C$2+7*(M$6-1) | N5: =$C$2+7*(N$6-1) | O5: =$C$2+7*(O$6-1) | P5: =$C$2+7*(P$6-1) | Q5: =$C$2+7*(Q$6-1) | R5: =$C$2+7*(R$6-1) | ... V5: =$C$2+7*(V$6-1)
A6: ID | B6: Tarea | C6: Responsable | D6: Sprint / Fase PMI | E6: Sem. inicio | F6: Duración (sem) | G6: Sem. fin | H6: Fecha inicio | I6: Fecha fin | J6: Depende de | K6: 1 | L6: 2 | M6: 3 | N6: 4 | O6: 5 | P6: 6 | Q6: 7 | R6: 8 | S6: 9 | T6: 10 | U6: 11 | V6: 12
A7: 1 | B7: Sprint 1 – Diseño y documentación | D7: Sprint 1 | E7: =MIN(E8:E9) | F7: =G7-E7+1 | G7: =MAX(G8:G9) | H7: =$C$2+7*(E7-1) | I7: =$C$2+7*(G7-1)+4
A8: 1.1 | B8: Contexto, arquitectura y decisiones técnicas (docs/) | C8: Abraham Castro | D8: Sprint 1 | E8: 1 | F8: 1 | G8: =E8+F8-1 | H8: =$C$2+7*(E8-1) | I8: =$C$2+7*(G8-1)+4 | J8: —
A9: 1.2 | B9: Pauta Nota 2, roles, RACI, Scrum/PMI y Carta Gantt | C9: Bárbara Saavedra | D9: Sprint 2 y 3 | E9: 2 | F9: 2 | G9: =E9+F9-1 | H9: =$C$2+7*(E9-1) | I9: =$C$2+7*(G9-1)+4 | J9: 1.1
A10: 2 | B10: Sprint 2 – Captura y visualización | D10: Sprint 2 | E10: =MIN(E11:E14) | F10: =G10-E10+1 | G10: =MAX(G11:G14) | H10: =$C$2+7*(E10-1) | I10: =$C$2+7*(G10-1)+4
A11: 2.1 | B11: Contrato de datos del dashboard y formato de telemetría | C11: Abraham Castro | D11: Sprint 2 | E11: 2 | F11: 1 | G11: =E11+F11-1 | H11: =$C$2+7*(E11-1) | I11: =$C$2+7*(G11-1)+4 | J11: 1.1
A12: 2.2 | B12: Broker MQTT EMQX (TLS, usuario y Client ID por dispositivo) | C12: Abraham Castro | D12: Sprint 2 | E12: 2 | F12: 1 | G12: =E12+F12-1 | H12: =$C$2+7*(E12-1) | I12: =$C$2+7*(G12-1)+4 | J12: 2.1
A13: 2.3 | B13: Dashboard React con datos simulados | C13: Abraham Castro | D13: Sprint 2 | E13: 2 | F13: 2 | G13: =E13+F13-1 | H13: =$C$2+7*(E13-1) | I13: =$C$2+7*(G13-1)+4 | J13: 2.1
A14: 2.4 | B14: Backend AWS: API Gateway, Lambda, DynamoDB y S3 | C14: Felipe Murúa | D14: Sprint 2 | E14: 2 | F14: 2 | G14: =E14+F14-1 | H14: =$C$2+7*(E14-1) | I14: =$C$2+7*(G14-1)+4 | J14: 2.1
A15: 3 | B15: Sprint 3 – Integración híbrida y demo | D15: Sprint 3 | E15: =MIN(E16:E20) | F15: =G15-E15+1 | G15: =MAX(G16:G20) | H15: =$C$2+7*(E15-1) | I15: =$C$2+7*(G15-1)+4
A16: 3.1 | B16: ESP32 en Wokwi publicando por MQTT | C16: Sebastián Fuentes | D16: Sprint 3 | E16: 2 | F16: 2 | G16: =E16+F16-1 | H16: =$C$2+7*(E16-1) | I16: =$C$2+7*(G16-1)+4 | J16: 2.2
A17: 3.2 | B17: Edge Gateway: SQLite, intervalos, alertas y sincronización | C17: Abraham Castro | D17: Sprint 3 | E17: 2 | F17: 2 | G17: =E17+F17-1 | H17: =$C$2+7*(E17-1) | I17: =$C$2+7*(G17-1)+4 | J17: 2.2, 2.4
A18: 3.3 | B18: Pruebas del Edge y simulación de corte de internet | C18: Lisandra González | D18: Sprint 3 | E18: 3 | F18: 1 | G18: =E18+F18-1 | H18: =$C$2+7*(E18-1) | I18: =$C$2+7*(G18-1)+4 | J18: 3.2
A19: 3.4 | B19: Cognito con MFA | C19: Felipe Murúa | D19: Sprint 3 | E19: 3 | F19: 1 | G19: =E19+F19-1 | H19: =$C$2+7*(E19-1) | I19: =$C$2+7*(G19-1)+4 | J19: 2.4
A20: 3.5 | B20: Casos de prueba y ensayo de la demo | C20: Abraham Castro | D20: Sprint 3 | E20: 3 | F20: 1 | G20: =E20+F20-1 | H20: =$C$2+7*(E20-1) | I20: =$C$2+7*(G20-1)+4 | J20: 3.1, 3.2
A21: 4 | B21: Implementación en Induplac (PMI) | D21: PMI | E21: =MIN(E22:E31) | F21: =G21-E21+1 | G21: =MAX(G22:G31) | H21: =$C$2+7*(E21-1) | I21: =$C$2+7*(G21-1)+4
A22: 4.1 | B22: Inicio: validar alcance y criterios de éxito con Induplac | C22: Abraham Castro | D22: Inicio | E22: 4 | F22: 1 | G22: =E22+F22-1 | H22: =$C$2+7*(E22-1) | I22: =$C$2+7*(G22-1)+4 | J22: 3.5
A23: 4.2 | B23: Planificación: diseño detallado, riesgos y compras (sensores, Raspberry Pi) | C23: Bárbara Saavedra | D23: Planificación | E23: 5 | F23: 1 | G23: =E23+F23-1 | H23: =$C$2+7*(E23-1) | I23: =$C$2+7*(G23-1)+4 | J23: 4.1
A24: 4.3 | B24: Instalación de sensores y red (VLAN IoT, VPN) | C24: Sebastián Fuentes | D24: Ejecución | E24: 6 | F24: 2 | G24: =E24+F24-1 | H24: =$C$2+7*(E24-1) | I24: =$C$2+7*(G24-1)+4 | J24: 4.2
A25: 4.4 | B25: Despliegue del Edge en la Raspberry Pi (RTC + NTP) | C25: Lisandra González | D25: Ejecución | E25: 6 | F25: 2 | G25: =E25+F25-1 | H25: =$C$2+7*(E25-1) | I25: =$C$2+7*(G25-1)+4 | J25: 4.2
A26: 4.5 | B26: Backend, Cognito y dashboard en producción | C26: Felipe Murúa | D26: Ejecución | E26: 6 | F26: 2 | G26: =E26+F26-1 | H26: =$C$2+7*(E26-1) | I26: =$C$2+7*(G26-1)+4 | J26: 4.2
A27: 4.6 | B27: Pruebas de seguridad, corte de red y permisos | C27: Felipe Murúa | D27: Monitoreo y control | E27: 8 | F27: 1 | G27: =E27+F27-1 | H27: =$C$2+7*(E27-1) | I27: =$C$2+7*(G27-1)+4 | J27: 4.3, 4.4, 4.5
A28: 4.7 | B28: Piloto en Local 1 y capacitación de usuarios | C28: Bárbara Saavedra | D28: Ejecución | E28: 9 | F28: 1 | G28: =E28+F28-1 | H28: =$C$2+7*(E28-1) | I28: =$C$2+7*(G28-1)+4 | J28: 4.6
A29: 4.8 | B29: Extensión a Local 2 | C29: Sebastián Fuentes | D29: Ejecución | E29: 10 | F29: 1 | G29: =E29+F29-1 | H29: =$C$2+7*(E29-1) | I29: =$C$2+7*(G29-1)+4 | J29: 4.7
A30: 4.9 | B30: Monitoreo y control (revisión semanal de avance y riesgos) | C30: Abraham Castro | D30: Monitoreo y control | E30: 4 | F30: 8 | G30: =E30+F30-1 | H30: =$C$2+7*(E30-1) | I30: =$C$2+7*(G30-1)+4 | J30: —
A31: 4.10 | B31: Cierre: aceptación, documentación y lecciones aprendidas | C31: Abraham Castro | D31: Cierre | E31: 12 | F31: 1 | G31: =E31+F31-1 | H31: =$C$2+7*(E31-1) | I31: =$C$2+7*(G31-1)+4 | J31: 4.8
A32: 5 | B32: Hitos | D32: Hitos | E32: =MIN(E33:E37) | F32: =G32-E32+1 | G32: =MAX(G33:G37) | H32: =$C$2+7*(E32-1) | I32: =$C$2+7*(G32-1)+4
A33: 5.1 | B33: ◆ Broker y backend en la nube operativos | C33: Equipo | D33: Hitos | E33: 2 | F33: 1 | G33: =E33+F33-1 | H33: =$C$2+7*(E33-1) | I33: =$C$2+7*(G33-1)+4 | J33: 2.2, 2.4
A34: 5.2 | B34: ◆ Demostración del prototipo (miércoles 21/10) | C34: Equipo | D34: Hitos | E34: 3 | F34: 1 | G34: =E34+F34-1 | H34: =$C$2+7*(E34-1) | I34: =$C$2+7*(G34-1)+4 | J34: 3.5
A35: 5.3 | B35: ◆ Acta de inicio con Induplac | C35: Equipo | D35: Hitos | E35: 4 | F35: 1 | G35: =E35+F35-1 | H35: =$C$2+7*(E35-1) | I35: =$C$2+7*(G35-1)+4 | J35: 4.1
A36: 5.4 | B36: ◆ Pruebas aprobadas | C36: Equipo | D36: Hitos | E36: 8 | F36: 1 | G36: =E36+F36-1 | H36: =$C$2+7*(E36-1) | I36: =$C$2+7*(G36-1)+4 | J36: 4.6
A37: 5.5 | B37: ◆ Puesta en marcha | C37: Equipo | D37: Hitos | E37: 11 | F37: 1 | G37: =E37+F37-1 | H37: =$C$2+7*(E37-1) | I37: =$C$2+7*(G37-1)+4 | J37: 4.8
B47: Leyenda (color de la barra = responsable)
B48: Abraham Castro
B49: Sebastián Fuentes
B50: Lisandra González
...

Sheet Roles
A1: Induplac IoT – Asignación de roles del equipo
A2: Actualizado el 18/10/2026 según lo construido en GitHub (tablero EN-CURSO y notas de avance).
A4: Integrante | B4: Rol | C4: Responsabilidades principales | D4: Carpeta del repositorio | E4: Sprint de mayor carga | F4: N.º de tareas detalladas | G4: Fortalezas
A5: Abraham Castro | B5: Jefe de proyecto, integración y desarrollo (broker, Edge y dashboard) | C5: Coordina el equipo y el repositorio (README, docs/, ramas y Pull Requests). Creó el broker EMQX, el dashboard React y el Edge Gateway en Python; armó el backend AWS junto a Felipe. Prepara los casos de prueba y la demo. | D5: docs/, dashboard/, edge/ | E5: Todos (transversal) | F5: =COUNTIF(Responsabilidades!$A:$A,A5) | G5: Por completar (cada integrante)
A6: Sebastián Fuentes | B6: Ingeniero IoT y simulación | C6: Sketch del ESP32 en Wokwi (Local 1 y Local 2): sensores simulados (CT, caudalímetro, UV), NTP, buffer de lecturas y publicación del JSON por MQTT en el broker EMQX (device_id + seq + ts). Escenarios de prueba de alertas. | D6: sensors/, simulation/ | E6: Sprint 2 y 3 | F6: =COUNTIF(Responsabilidades!$A:$A,A6) | G6: Por completar (cada integrante)
A7: Lisandra González | B7: Pruebas del Edge y modo offline | C7: Prueba el Edge Gateway (edge/) con el simulador y con Wokwi, ejecuta la simulación de corte de internet, verifica la sincronización al volver la conexión (ONLINE / OFFLINE / SINCRONIZANDO, lotes de 50, sin duplicados) y documenta las evidencias. En la implementación, despliega el Edge en la Raspberry Pi. | D7: edge/ | E7: Sprint 3 | F7: =COUNTIF(Responsabilidades!$A:$A,A7) | G7: Por completar (cada integrante)
A8: Felipe Murúa | B8: Cloud, backend y ciberseguridad | C8: AWS en el Learner Lab: API Gateway, Lambda (Python), DynamoDB y S3 para publicar el dashboard; reglas de alerta; Cognito con MFA; IAM, TLS, clave de ingesta y cumplimiento de la Ley 19.628. | D8: backend/, infrastructure/ | E8: Sprint 2 y 3 | F8: =COUNTIF(Responsabilidades!$A:$A,A8) | G8: Por completar (cada integrante)
A9: Bárbara Saavedra | B9: Planificación y frontend | C9: Roles, matriz RACI, planificación Scrum y PMI, y Carta Gantt (tareas 9, 10, 13 y 14). Apoya el dashboard: revisión de las vistas y capacitación de usuarios en la implementación. | D9: docs/, dashboard/ | E9: Sprint 3 e implementación | F9: =COUNTIF(Responsabilidades!$A:$A,A9) | G9: Por completar (cada integrante)
E10: Total tareas | F10: =SUM(F5:F9)

Sheet RACI
A1: Induplac IoT – Matriz RACI
A2: R = Responsable (hace el trabajo) · A = Aprobador (responde por el resultado; uno solo por tarea) · C = Consultado · I = Informado · A/R = hace el trabajo y responde por él. · 10 actividades, como pide la pauta (6 a 10).
A4: N.º | B4: Tarea | C4: Abraham Castro Jefe de proyecto, broker, Edge y dashboard | D4: Sebastián Fuentes IoT y simulación | E4: Lisandra González Pruebas del Edge y modo offline | F4: Felipe Murúa Cloud y ciberseguridad | G4: Bárbara Saavedra Planificación y frontend | H4: N.º de A | I4: N.º de R | J4: Control
A5: 1 | B5: Captura IoT: ESP32 en Wokwi, payload JSON (device_id + seq + ts) y publicación MQTT | C5: C | D5: A/R | E5: I | F5: I | G5: I | H5: =COUNTIF(C5:G5,"A*") | I5: =COUNTIF(C5:G5,"*R*") | J5: =IF(AND(H5=1,I5>=1),"OK","Revisar")
A6: 2 | B6: Broker MQTT EMQX (TLS, usuario y Client ID por dispositivo) | C6: A/R | D6: C | E6: I | F6: C | G6: I | H6: =COUNTIF(C6:G6,"A*") | I6: =COUNTIF(C6:G6,"*R*") | J6: =IF(AND(H6=1,I6>=1),"OK","Revisar")
A7: 3 | B7: Edge Gateway: SQLite, intervalos de 15 min y alertas locales | C7: A/R | D7: C | E7: C | F7: C | G7: I | H7: =COUNTIF(C7:G7,"A*") | I7: =COUNTIF(C7:G7,"*R*") | J7: =IF(AND(H7=1,I7>=1),"OK","Revisar")
A8: 4 | B8: Modo offline y sincronización (healthcheck, lotes de 50, idempotencia) y sus pruebas | C8: A/R | D8: I | E8: R | F8: C | G8: I | H8: =COUNTIF(C8:G8,"A*") | I8: =COUNTIF(C8:G8,"*R*") | J8: =IF(AND(H8=1,I8>=1),"OK","Revisar")
A9: 5 | B9: Backend AWS: API Gateway, Lambda, DynamoDB, S3 y reglas de alerta | C9: R | D9: I | E9: C | F9: A/R | G9: I | H9: =COUNTIF(C9:G9,"A*") | I9: =COUNTIF(C9:G9,"*R*") | J9: =IF(AND(H9=1,I9>=1),"OK","Revisar")
A10: 6 | B10: Dashboard React (vistas por sede, alertas, histórico, panel de demo) | C10: A/R | D10: I | E10: I | F10: C | G10: C | H10: =COUNTIF(C10:G10,"A*") | I10: =COUNTIF(C10:G10,"*R*") | J10: =IF(AND(H10=1,I10>=1),"OK","Revisar")
A11: 7 | B11: Seguridad: Cognito con MFA, permisos por usuario, IAM, TLS, VPN documentada, Ley 19.628 | C11: C | D11: I | E11: I | F11: A/R | G11: I | H11: =COUNTIF(C11:G11,"A*") | I11: =COUNTIF(C11:G11,"*R*") | J11: =IF(AND(H11=1,I11>=1),"OK","Revisar")
A12: 8 | B12: Planificación: roles, RACI, Scrum, PMI y Carta Gantt | C12: C | D12: C | E12: C | F12: C | G12: A/R | H12: =COUNTIF(C12:G12,"A*") | I12: =COUNTIF(C12:G12,"*R*") | J12: =IF(AND(H12=1,I12>=1),"OK","Revisar")
A13: 9 | B13: Pruebas integrales y simulación de fallas (corte de red, valores absurdos, alertas) | C13: A | D13: R | E13: R | F13: C | G13: C | H13: =COUNTIF(C13:G13,"A*") | I13: =COUNTIF(C13:G13,"*R*") | J13: =IF(AND(H13=1,I13>=1),"OK","Revisar")
A14: 10 | B14: Documentación, Pull Requests, demo y presentación final | C14: A/R | D14: R | E14: R | F14: R | G14: R | H14: =COUNTIF(C14:G14,"A*") | I14: =COUNTIF(C14:G14,"*R*") | J14: =IF(AND(H14=1,I14>=1),"OK","Revisar")
B15: Total de tareas como R (hace el trabajo) | C15: =COUNTIF(C5:C14,"*R*") | D15: =COUNTIF(D5:D14,"*R*") | E15: =COUNTIF(E5:E14,"*R*") | F15: =COUNTIF(F5:F14,"*R*") | G15: =COUNTIF(G5:G14,"*R*")
B16: Total de tareas como A (aprueba) | C16: =COUNTIF(C5:C14,"A*") | D16: =COUNTIF(D5:D14,"A*") | E16: =COUNTIF(E5:E14,"A*") | F16: =COUNTIF(F5:F14,"A*") | G16: =COUNTIF(G5:G14,"A*")
B18: Leyenda
A19: A/R | B19: Hace el trabajo y responde por el resultado
A20: A | B20: Aprueba / responde por el resultado
A21: R | B21: Responsable de ejecutar
A22: C | B22: Consultado antes de decidir
A23: I | B23: Informado del avance

Sheet Responsabilidades
A1: Integrante | B1: Rol | C1: Tarea | D1: Sprint | E1: Estado
A2: Abraham Castro | B2: Jefe de proyecto, integración y desarrollo (broker, Edge y dashboard) | C2: Coordinación del equipo, repositorio y Pull Requests | D2: Todos | E2: En curso
A3: Abraham Castro | B3: Jefe de proyecto, integración y desarrollo (broker, Edge y dashboard) | C3: Broker MQTT EMQX (TLS, usuario y Client ID por dispositivo) | D3: Sprint 2 | E3: Listo (PR #9)
A4: Abraham Castro | B4: Jefe de proyecto, integración y desarrollo (broker, Edge y dashboard) | C4: Dashboard React con datos simulados y conexión a la API | D4: Sprint 2 y 3 | E4: En curso
A5: Abraham Castro | B5: Jefe de proyecto, integración y desarrollo (broker, Edge y dashboard) | C5: Edge Gateway en Python: SQLite, intervalos de 15 min, alertas y sincronización | D5: Sprint 3 | E5: En curso
A6: Abraham Castro | B6: Jefe de proyecto, integración y desarrollo (broker, Edge y dashboard) | C6: Backend AWS junto a Felipe (Lambda, DynamoDB, API Gateway, S3) | D6: Sprint 2 | E6: Listo (falta re-deploy)
A7: Abraham Castro | B7: Jefe de proyecto, integración y desarrollo (broker, Edge y dashboard) | C7: Casos de prueba y ensayo de la demo | D7: Sprint 3 | E7: Pendiente
A8: Sebastián Fuentes | B8: Ingeniero IoT y simulación | C8: Sketch ESP32 en Wokwi (Local 1 y Local 2) | D8: Sprint 2 y 3 | E8: En curso
A9: Sebastián Fuentes | B9: Ingeniero IoT y simulación | C9: Sensores simulados: CT (kW), caudalímetro (agua) y UV | D9: Sprint 3 | E9: En curso
A10: Sebastián Fuentes | B10: Ingeniero IoT y simulación | C10: Publicación MQTT del JSON (device_id + seq + ts) en el broker | D10: Sprint 3 | E10: En curso
A11: Sebastián Fuentes | B11: Ingeniero IoT y simulación | C11: NTP y buffer de lecturas sin conexión | D11: Sprint 3 | E11: Pendiente
A12: Sebastián Fuentes | B12: Ingeniero IoT y simulación | C12: Escenarios de prueba de alertas (kW +20 %, UV ≥ 8, agua) | D12: Sprint 3 | E12: Pendiente
... A28: Bárbara Saavedra | B28: Planificación y frontend | C28: Capacitación de usuarios del dashboard | D28: Implementación | E28: Pendiente
